Workbook

Sheet product_list
A1: MA_Number | B1: Product_Name | C1: alt_name | D1: type_code | E1: Description | F1: Is_Assembly | G1: parent_ma | H1: Part_Number | I1: Part_Qty | J1: Part_Length | K1: Part_Width | L1: Part_Height | M1: color_code | N1: material_code | O1: process_cut | P1: process_mill | Q1: group_processing | R1: dimension_x_g | S1: dimension_y_g | T1: dimension_z_g | U1: qty_per_group | V1: is_3d_part | W1: Assembly_Order | X1: batch_id | Y1: qty | Z1: price_offer_num | AA1: qty_per_board | AB1: jb_qty | AC1: vlookup_name | AD1: vlookup_qty | AE1: path
A2: 10.21.80758A | B2: 7075231830 | C2: X1PO2395 | D2: CH | F2: FALSE | I2: 1 | J2: 90 | K2: 90 | L2: 65 | M2: BK | N2: POM | O2: TRUE | Y2: =IFERROR(AB2*AA2,0) -> 0 | AA2: =AD2 | AB2: 28 | AC2: =IFERROR(VLOOKUP(B2,vlookup!$A$16:$A$150,1,FALSE),"") | AD2: =IFERROR(VLOOKUP(B2,vlookup!$A$16:$G$150,11,FALSE),"")
A3: 10.21.72966C | B3: 7075231930 | C3: 7035964930, X1PO2518, X1PP5823 | D3: CH | F3: FALSE | I3: 1 | J3: 83 | K3: 57 | L3: 77 | M3: BK | N3: POM | O3: TRUE | X3: 19 | Y3: =IFERROR(AB3*AA3,0) -> 0 | Z3: I10130 | AA3: =AD3 | AB3: 28 | AC3: =IFERROR(VLOOKUP(B3,vlookup!$A$16:$A$150,1,FALSE),"") -> 7075231930 | AD3: =IFERROR(VLOOKUP(B3,vlookup!$A$16:$G$150,11,FALSE),"")
A4: 10.21.72968A | B4: 7075236930 | C4: X1PO2363 | D4: CH | F4: FALSE | I4: 1 | J4: 60 | K4: 43 | L4: 65 | M4: BK | N4: POM | O4: TRUE | Y4: =IFERROR(AB4*AA4,0) -> 0 | AA4: =AD4 | AB4: 28 | AC4: =IFERROR(VLOOKUP(B4,vlookup!$A$16:$A$150,1,FALSE),"") | AD4: =IFERROR(VLOOKUP(B4,vlookup!$A$16:$G$150,11,FALSE),"")
A5: 10.21.83798A | B5: 7075244730 | D5: CH | F5: FALSE | I5: 1 | J5: 60 | K5: 37 | L5: 60 | M5: BK | N5: POM | O5: TRUE | Y5: =IFERROR(AB5*AA5,0) -> 0 | AA5: =AD5 | AB5: 28 | AC5: =IFERROR(VLOOKUP(B5,vlookup!$A$16:$A$150,1,FALSE),"") -> 7075244730 | AD5: =IFERROR(VLOOKUP(B5,vlookup!$A$16:$G$150,11,FALSE),"")
A6: 10.21.35131A | B6: 71186354 | D6: CH | F6: FALSE | I6: 1 | J6: 48 | K6: 43 | L6: 51 | M6: WH | N6: POM | O6: TRUE | X6: 19 | Y6: =IFERROR(AB6*AA6,0) -> 0 | Z6: I10130 | AA6: =AD6 | AB6: 28 | AC6: =IFERROR(VLOOKUP(B6,vlookup!$A$16:$A$150,1,FALSE),"") -> 71186354 | AD6: =IFERROR(VLOOKUP(B6,vlookup!$A$16:$G$150,11,FALSE),"")
A7: 10.21.35334A | B7: 7118641830+7173344320 | D7: CH | F7: FALSE | I7: 1 | J7: 64 | K7: 50 | L7: 75 | M7: BK | N7: POM | O7: TRUE | Y7: =IFERROR(AB7*AA7,0) -> 0 | AA7: =AD7 | AB7: 28 | AC7: =IFERROR(VLOOKUP(B7,vlookup!$A$16:$A$150,1,FALSE),"") -> 7118641830+7173344320 | AD7: =IFERROR(VLOOKUP(B7,vlookup!$A$16:$G$150,11,FALSE),"")
A8: 10.21.89505A | B8: 71186683+7173344320 | D8: CH | F8: FALSE | I8: 1 | J8: 73 | K8: 74 | L8: 65 | M8: WH | N8: POM | O8: TRUE | Y8: =IFERROR(AB8*AA8,0) -> 0 | AA8: =AD8 | AB8: 28 | AC8: =IFERROR(VLOOKUP(B8,vlookup!$A$16:$A$150,1,FALSE),"") -> 71186683+7173344320 | AD8: =IFERROR(VLOOKUP(B8,vlookup!$A$16:$G$150,11,FALSE),"")
A9: 10.21.77121A | B9: 7118670020 | D9: CH | F9: FALSE | I9: 1 | J9: 50 | K9: 47 | L9: 51 | M9: RD | N9: POM | O9: TRUE | X9: 19 | Y9: =IFERROR(AB9*AA9,0) -> 0 | Z9: I10130 | AA9: =AD9 | AB9: 28 | AC9: =IFERROR(VLOOKUP(B9,vlookup!$A$16:$A$150,1,FALSE),"") -> 7118670020 | AD9: =IFERROR(VLOOKUP(B9,vlookup!$A$16:$G$150,11,FALSE),"")
A10: 10.21.27914A | B10: 7119101830+7274131020 | D10: CH | F10: FALSE | I10: 1 | J10: 56 | K10: 48 | L10: 50 | M10: RD | N10: POM | O10: TRUE | Y10: =IFERROR(AB10*AA10,0) -> 0 | AA10: =AD10 | AB10: 28 | AC10: =IFERROR(VLOOKUP(B10,vlookup!$A$16:$A$150,1,FALSE),"") -> 7119101830+7274131020 | AD10: =IFERROR(VLOOKUP(B10,vlookup!$A$16:$G$150,11,FALSE),"")
A11: 10.21.36860F | B11: 7119127830+7234894130A | D11: CH | F11: FALSE | I11: 1 | J11: 57 | K11: 48 | L11: 50 | M11: BK | N11: POM | O11: TRUE | V11: TRUE | Y11: =IFERROR(AB11*AA11,0) -> 0 | AA11: =AD11 | AB11: 28 | AC11: =IFERROR(VLOOKUP(B11,vlookup!$A$16:$A$150,1,FALSE),"") -> 7119127830+7234894130A | AD11: =IFERROR(VLOOKUP(B11,vlookup!$A$16:$G$150,11,FALSE),"")
A12: 10.21.54168C | B12: 7119131530 | D12: CH | F12: FALSE | I12: 1 | J12: 42 | K12: 34 | L12: 42 | M12: BK | N12: POM | O12: TRUE | X12: 19 | Y12: =IFERROR(AB12*AA12,0) -> 0 | Z12: I10130 | AA12: =AD12 | AB12: 28 | AC12: =IFERROR(VLOOKUP(B12,vlookup!$A$16:$A$150,1,FALSE),"") -> 7119131530 | AD12: =IFERROR(VLOOKUP(B12,vlookup!$A$16:$G$150,11,FALSE),"")
A13: 10.21.80751A | B13: 7119140530+7119140640+72741359 | D13: CH | F13: FALSE | I13: 1 | J13: 90 | K13: 50 | L13: 52 | M13: WH | N13: POM | O13: TRUE | V13: TRUE | Y13: =IFERROR(AB13*AA13,0) -> 0 | AA13: =AD13 | AB13: 28 | AC13: =IFERROR(VLOOKUP(B13,vlookup!$A$16:$A$150,1,FALSE),"") -> 7119140530+7119140640+72741359 | AD13: =IFERROR(VLOOKUP(B13,vlookup!$A$16:$G$150,11,FALSE),"")
A14: 10.21.35002C | B14: 7119146730 | D14: CH | F14: FALSE | I14: 1 | J14: 42 | K14: 38 | L14: 42 | M14: BK | N14: POM | O14: TRUE | Y14: =IFERROR(AB14*AA14,0) -> 0 | AA14: =AD14 | AB14: 28 | AC14: =IFERROR(VLOOKUP(B14,vlookup!$A$16:$A$150,1,FALSE),"") -> 7119146730 | AD14: =IFERROR(VLOOKUP(B14,vlookup!$A$16:$G$150,11,FALSE),"")
A15: 10.21.35003A | B15: 71191993 | D15: CH | F15: FALSE | I15: 1 | J15: 42 | K15: 35 | L15: 44 | M15: WH | N15: POM | O15: TRUE | X15: 19 | Y15: =IFERROR(AB15*AA15,0) -> 0 | Z15: I10130 | AA15: =AD15 | AB15: 28 | AC15: =IFERROR(VLOOKUP(B15,vlookup!$A$16:$A$150,1,FALSE),"") -> 71191993 | AD15: =IFERROR(VLOOKUP(B15,vlookup!$A$16:$G$150,11,FALSE),"")
A16: 10.21.77073A | B16: 71196180 | D16: CH | F16: FALSE | I16: 1 | J16: 40 | K16: 40 | L16: 52 | M16: WH | N16: POM | O16: TRUE | Y16: =IFERROR(AB16*AA16,0) -> 0 | AA16: =AD16 | AB16: 28 | AC16: =IFERROR(VLOOKUP(B16,vlookup!$A$16:$A$150,1,FALSE),"") | AD16: =IFERROR(VLOOKUP(B16,vlookup!$A$16:$G$150,11,FALSE),"")
A17: 10.21.77045A | B17: 7183288530+7183288630+72742612 - 7119632530+7119632630+72742614A | D17: CH | F17: FALSE | I17: 1 | J17: 82 | K17: 77 | L17: 52 | M17: WH | N17: POM | O17: TRUE | Y17: =IFERROR(AB17*AA17,0) -> 0 | AA17: =AD17 | AB17: 28 | AC17: =IFERROR(VLOOKUP(B17,vlookup!$A$16:$A$150,1,FALSE),"") | AD17: =IFERROR(VLOOKUP(B17,vlookup!$A$16:$G$150,11,FALSE),"")
A18: 10.21.83680A | B18: 7119639830 | D18: CH | F18: FALSE | I18: 1 | J18: 46 | K18: 40 | L18: 48 | M18: BK | N18: POM | O18: TRUE | Y18: =IFERROR(AB18*AA18,0) -> 0 | AA18: =AD18 | AB18: 28 | AC18: =IFERROR(VLOOKUP(B18,vlookup!$A$16:$A$150,1,FALSE),"") -> 7119639830 | AD18: =IFERROR(VLOOKUP(B18,vlookup!$A$16:$G$150,11,FALSE),"")
A19: 10.21.36271A | B19: 71196401 | D19: CH | F19: FALSE | I19: 1 | J19: 42 | K19: 39 | L19: 46 | M19: WH | N19: POM | O19: TRUE | X19: 19 | Y19: =IFERROR(AB19*AA19,0) -> 0 | Z19: I10130 | AA19: =AD19 | AB19: 28 | AC19: =IFERROR(VLOOKUP(B19,vlookup!$A$16:$A$150,1,FALSE),"") -> 71196401 | AD19: =IFERROR(VLOOKUP(B19,vlookup!$A$16:$G$150,11,FALSE),"")
A20: 10.21.83709A | B20: 7119641970 | D20: CH | F20: FALSE | I20: 1 | J20: 42 | K20: 36 | L20: 46 | M20: YE | N20: POM | O20: TRUE | Y20: =IFERROR(AB20*AA20,0) -> 0 | AA20: =AD20 | AB20: 28 | AC20: =IFERROR(VLOOKUP(B20,vlookup!$A$16:$A$150,1,FALSE),"") -> 7119641970 | AD20: =IFERROR(VLOOKUP(B20,vlookup!$A$16:$G$150,11,FALSE),"")
A21: 10.21.47236A | B21: 71196506 | D21: CH | F21: FALSE | I21: 1 | J21: 42 | K21: 33 | L21: 47 | M21: WH | N21: POM | O21: TRUE | V21: TRUE | Y21: =IFERROR(AB21*AA21,0) -> 0 | AA21: =AD21 | AB21: 28 | AC21: =IFERROR(VLOOKUP(B21,vlookup!$A$16:$A$150,1,FALSE),"") -> 71196506 | AD21: =IFERROR(VLOOKUP(B21,vlookup!$A$16:$G$150,11,FALSE),"")
A22: 10.21.83671B | B22: 71196683+7173344320+X1PO2488 | D22: CH | F22: FALSE | I22: 1 | J22: 61 | K22: 50 | L22: 87 | M22: WH | N22: POM | O22: TRUE | Y22: =IFERROR(AB22*AA22,0) -> 0 | AA22: =AD22 | AB22: 28 | AC22: =IFERROR(VLOOKUP(B22,vlookup!$A$16:$A$150,1,FALSE),"") | AD22: =IFERROR(VLOOKUP(B22,vlookup!$A$16:$G$150,11,FALSE),"")
A23: 10.21.77085A | B23: 7119668820 | D23: CH | F23: FALSE | I23: 1 | J23: 40 | K23: 37 | L23: 52 | M23: RD | N23: POM | O23: TRUE | Y23: =IFERROR(AB23*AA23,0) -> 0 | AA23: =AD23 | AB23: 28 | AC23: =IFERROR(VLOOKUP(B23,vlookup!$A$16:$A$150,1,FALSE),"") -> 7119668820 | AD23: =IFERROR(VLOOKUP(B23,vlookup!$A$16:$G$150,11,FALSE),"")
A24: 10.21.73050A | B24: 7119670830+7274290770A | D24: CH | F24: FALSE | I24: 1 | J24: 55 | K24: 67 | L24: 52 | M24: YE | N24: POM | O24: TRUE | Y24: =IFERROR(AB24*AA24,0) -> 0 | AA24: =AD24 | AB24: 28 | AC24: =IFERROR(VLOOKUP(B24,vlookup!$A$16:$A$150,1,FALSE),"") -> 7119670830+7274290770A | AD24: =IFERROR(VLOOKUP(B24,vlookup!$A$16:$G$150,11,FALSE),"")
A25: 10.21.80748A | B25: 71196714 | D25: CH | F25: FALSE | I25: 1 | J25: 45 | K25: 38 | L25: 59 | M25: WH | N25: POM | O25: TRUE | Y25: =IFERROR(AB25*AA25,0) -> 0 | AA25: =AD25 | AB25: 28 | AC25: =IFERROR(VLOOKUP(B25,vlookup!$A$16:$A$150,1,FALSE),"") -> 71196714 | AD25: =IFERROR(VLOOKUP(B25,vlookup!$A$16:$G$150,11,FALSE),"")
A26: 10.21.42593A | B26: 7119648630+7274171430A | D26: CH | F26: FALSE | I26: 1 | J26: 62 | K26: 67 | L26: 60 | M26: BK | N26: POM | O26: TRUE | Y26: =IFERROR(AB26*AA26,0) -> 0 | AA26: =AD26 | AB26: 28 | AC26: =IFERROR(VLOOKUP(B26,vlookup!$A$16:$A$150,1,FALSE),"") -> 7119648630+7274171430A | AD26: =IFERROR(VLOOKUP(B26,vlookup!$A$16:$G$150,11,FALSE),"")
A27: 10.21.77076A | B27: 71781405 | D27: CH | F27: FALSE | I27: 1 | J27: 40 | K27: 39 | L27: 45 | M27: WH | N27: POM | O27: TRUE | Y27: =IFERROR(AB27*AA27,0) -> 0 | AA27: =AD27 | AB27: 28 | AC27: =IFERROR(VLOOKUP(B27,vlookup!$A$16:$A$150,1,FALSE),"") | AD27: =IFERROR(VLOOKUP(B27,vlookup!$A$16:$G$150,11,FALSE),"")
A28: 10.21.72974A | B28: 7183288530+7183288630+72742612A | D28: CH | F28: FALSE | I28: 1 | J28: 82 | K28: 77 | L28: 52 | M28: WH | N28: POM | O28: TRUE | Y28: =IFERROR(AB28*AA28,0) -> 0 | AA28: =AD28 | AB28: 28 | AC28: =IFERROR(VLOOKUP(B28,vlookup!$A$16:$A$150,1,FALSE),"") -> 7183288530+7183288630+72742612A | AD28: =IFERROR(VLOOKUP(B28,vlookup!$A$16:$G$150,11,FALSE),"")
A29: 10.21.77049A | B29: 7185173030+7185173130+72742608 | D29: CH | F29: FALSE | I29: 1 | J29: 92 | K29: 75 | L29: 52 | M29: WH | N29: POM | O29: TRUE | Y29: =IFERROR(AB29*AA29,0) -> 0 | AA29: =AD29 | AB29: 28 | AC29: =IFERROR(VLOOKUP(B29,vlookup!$A$16:$A$150,1,FALSE),"") -> 7185173030+7185173130+72742608 | AD29: =IFERROR(VLOOKUP(B29,vlookup!$A$16:$G$150,11,FALSE),"")
A30: 10.21.42674D | B30: 7187903970+7187904070+7274060970 | D30: CH | F30: FALSE | I30: 1 | J30: 92 | K30: 68 | L30: 55 | M30: YE | N30: POM | O30: TRUE | Y30: =IFERROR(AB30*AA30,0) -> 0 | AA30: =AD30 | AB30: 28 | AC30: =IFERROR(VLOOKUP(B30,vlookup!$A$16:$A$150,1,FALSE),"") | AD30: =IFERROR(VLOOKUP(B30,vlookup!$A$16:$G$150,11,FALSE),"")
A31: 10.21.72978A | B31: 71884821+7134425740 | D31: CH | F31: FALSE | I31: 1 | J31: 51 | K31: 51 | L31: 66 | M31: WH | N31: POM | O31: TRUE | X31: 19 | Y31: =IFERROR(AB31*AA31,0) -> 0 | Z31: I10130 | AA31: =AD31 | AB31: 28 | AC31: =IFERROR(VLOOKUP(B31,vlookup!$A$16:$A$150,1,FALSE),"") -> 71884821+7134425740 | AD31: =IFERROR(VLOOKUP(B31,vlookup!$A$16:$G$150,11,FALSE),"")
A32: 10.21.83656D | B32: 7188503730+7174152230A(7177097330) | D32: CH | F32: FALSE | I32: 1 | J32: 84 | K32: 78 | L32: 49 | M32: BK | N32: POM | O32: TRUE | Y32: =IFERROR(AB32*AA32,0) -> 0 | AA32: =AD32 | AB32: 28 | AC32: =IFERROR(VLOOKUP(B32,vlookup!$A$16:$A$150,1,FALSE),"") | AD32: =IFERROR(VLOOKUP(B32,vlookup!$A$16:$G$150,11,FALSE),"")
A33: 10.21.83657E | B33: 7188503730+7174152230A(7177097330) | D33: CH | F33: FALSE | I33: 1 | J33: 84 | K33: 78 | L33: 49 | M33: BK | N33: POM | O33: TRUE | Y33: =IFERROR(AB33*AA33,0) -> 0 | AA33: =AD33 | AB33: 28 | AC33: =IFERROR(VLOOKUP(B33,vlookup!$A$16:$A$150,1,FALSE),"") | AD33: =IFERROR(VLOOKUP(B33,vlookup!$A$16:$G$150,11,FALSE),"")
A34: 10.21.35851A | B34: 7189663170 | D34: CH | F34: FALSE | I34: 1 | J34: 44 | K34: 36 | L34: 46 | M34: YE | N34: POM | O34: TRUE | Y34: =IFERROR(AB34*AA34,0) -> 0 | AA34: =AD34 | AB34: 28 | AC34: =IFERROR(VLOOKUP(B34,vlookup!$A$16:$A$150,1,FALSE),"") -> 7189663170 | AD34: =IFERROR(VLOOKUP(B34,vlookup!$A$16:$G$150,11,FALSE),"")
A35: 10.21.76941A | B35: 7189811530+7289811830+72741554 | D35: CH | F35: FALSE | I35: 1 | J35: 124 | K35: 76 | L35: 62 | M35: WH | N35: POM | O35: TRUE | Y35: =IFERROR(AB35*AA35,0) -> 0 | AA35: =AD35 | AB35: 28 | AC35: =IFERROR(VLOOKUP(B35,vlookup!$A$16:$A$150,1,FALSE),"") -> 7189811530+7289811830+72741554 | AD35: =IFERROR(VLOOKUP(B35,vlookup!$A$16:$G$150,11,FALSE),"")
A36: 10.21.28074A | B36: 71899503 | D36: CH | F36: FALSE | I36: 1 | J36: 40 | K36: 32 | L36: 47 | M36: WH | N36: POM | O36: TRUE | X36: 19 | Y36: =IFERROR(AB36*AA36,0) -> 0 | Z36: I10130 | AA36: =AD36 | AB36: 28 | AC36: =IFERROR(VLOOKUP(B36,vlookup!$A$16:$A$150,1,FALSE),"") -> 71899503 | AD36: =IFERROR(VLOOKUP(B36,vlookup!$A$16:$G$150,11,FALSE),"")
A37: 10.21.76956B | B37: 7189982830 | D37: CH | F37: FALSE | I37: 1 | J37: 42 | K37: 42 | L37: 51 | M37: BK | N37: POM | O37: TRUE | Y37: =IFERROR(AB37*AA37,0) -> 0 | AA37: =AD37 | AB37: 28 | AC37: =IFERROR(VLOOKUP(B37,vlookup!$A$16:$A$150,1,FALSE),"") -> 7189982830 | AD37: =IFERROR(VLOOKUP(B37,vlookup!$A$16:$G$150,11,FALSE),"")
A38: 10.21.47066D | B38: 7189668330+7274135020A | D38: CH | F38: FALSE | I38: 1 | J38: 68 | K38: 65 | L38: 50 | M38: RD | N38: POM | O38: TRUE | V38: TRUE | Y38: =IFERROR(AB38*AA38,0) -> 0 | AA38: =AD38 | AB38: 28 | AC38: =IFERROR(VLOOKUP(B38,vlookup!$A$16:$A$150,1,FALSE),"") -> 7189668330+7274135020A | AD38: =IFERROR(VLOOKUP(B38,vlookup!$A$16:$G$150,11,FALSE),"")
A39: 10.21.47047D | B39: 7189668330+7274136090A | D39: CH | F39: FALSE | I39: 1 | J39: 68 | K39: 65 | L39: 52 | M39: BL | N39: POM | O39: TRUE | V39: TRUE | Y39: =IFERROR(AB39*AA39,0) -> 0 | AA39: =AD39 | AB39: 28 | AC39: =IFERROR(VLOOKUP(B39,vlookup!$A$16:$A$150,1,FALSE),"") -> 7189668330+7274136090A | AD39: =IFERROR(VLOOKUP(B39,vlookup!$A$16:$G$150,11,FALSE),"")
A40: 10.21.47065D | B40: 7189730210+7274146260A | D40: CH | F40: FALSE | I40: 1 | J40: 68 | K40: 65 | L40: 50 | M40: GN | N40: POM | O40: TRUE | V40: TRUE | Y40: =IFERROR(AB40*AA40,0) -> 0 | AA40: =AD40 | AB40: 28 | AC40: =IFERROR(VLOOKUP(B40,vlookup!$A$16:$A$150,1,FALSE),"") -> 7189730210+7274146260A | AD40: =IFERROR(VLOOKUP(B40,vlookup!$A$16:$G$150,11,FALSE),"")
...

Sheet vlookup
A1: code | B1: name | C1: qty | D1: result code | E1: qty
A2: 323 | B2: test | C2: 3 | D2: =VLOOKUP(A2, $E$2:$E$15, 1, FALSE) -> #N/A | E2: 3
A3: 33323 | B3: test1 | C3: 4 | D3: =VLOOKUP(A3, $E$2:$E$15, 1, FALSE) -> #N/A
A4: 444 | B4: test2 | C4: 5 | D4: =VLOOKUP(A4, $E$2:$E$15, 1, FALSE) -> #N/A | E4: 5
A5: 5 | B5: oo | C5: 3 | D5: =VLOOKUP(A5, $E$2:$E$15, 1, FALSE) -> 5 | E5: 4
D6: =VLOOKUP(A6, $E$2:$E$15, 1, FALSE) -> #N/A | E6: 3
A7: 324444 | B7: test4 | C7: 66 | D7: =VLOOKUP(A7, $E$2:$E$15, 1, FALSE) -> #N/A
D8: =VLOOKUP(A8, $E$2:$E$15, 1, FALSE) -> #N/A | E8: 3
D9: =VLOOKUP(A9, $E$2:$E$15, 1, FALSE) -> #N/A
D10: =VLOOKUP(A10, $E$2:$E$15, 1, FALSE) -> #N/A
D11: =VLOOKUP(A11, $E$2:$E$15, 1, FALSE) -> #N/A
D12: =VLOOKUP(A12, $E$2:$E$15, 1, FALSE) -> #N/A
D13: =VLOOKUP(A13, $E$2:$E$15, 1, FALSE) -> #N/A
D14: =VLOOKUP(A14, $E$2:$E$15, 1, FALSE) -> #N/A
A15: name | D15: type | E15: sc35h | F15: sc35h true | G15: qty | I15: batch | J15: stock
A16: 7003756102 | B16: original | C16: ok | D16: ch | G16: 1 | H16: =G16*28 -> 28 | I16: 19
A17: 7035964930 | B17: original | C17: ok | D17: ch | G17: 1 | H17: =G17*28 -> 28
A18: 7035990430 | B18: original | C18: gr | D18: ch | G18: 2 | H18: =G18*28 -> 56 | I18: 19
A19: 7035990930 | B19: original | C19: gr | D19: ch | G19: 1 | H19: =G19*28 -> 28 | I19: 19
A20: 7047052330D_DP | B20: original | C20: clip db | D20: clip | G20: 2 | H20: =G20*28 -> 56 | I20: 20
A21: 7047135830S_DP | B21: original | C21: clip db | D21: clip | G21: 1 | H21: =G21*28 -> 28 | I21: 20
A22: 7047186030 | B22: original | C22: clip | D22: clip | G22: 30 | H22: =G22*28 -> 840 | I22: 19 | J22: 119 | K22: not in production
A23: 7047186030D_DP | B23: original | C23: clip db | D23: clip | G23: 1 | H23: =G23*28 -> 28 | I23: 20
A24: 7047186030S_DP | B24: original | C24: clip db | D24: clip | G24: 3 | H24: =G24*28 -> 84 | I24: 20
A25: 7047186030U_DP | B25: original | C25: clip db | D25: clip | G25: 1 | H25: =G25*28 -> 28 | I25: 20
A26: 7052161430S_DP | B26: original | C26: clip db | D26: clip | G26: 1 | H26: =G26*28 -> 28 | I26: 20
A27: 7075181330 | B27: original | C27: ok | D27: ch | G27: 1 | H27: =G27*28 -> 28
A28: 7075231930 | B28: original | C28: gr | D28: ch | G28: 1 | H28: =G28*28 -> 28 | I28: 19 | J28: 2
A29: 7075244730 | B29: original | C29: ok | D29: ch | G29: 1 | H29: =G29*28 -> 28
A30: 7118605030+7152511030 | B30: original | C30: ok | D30: ch | G30: 2 | H30: =G30*28 -> 56
A31: 71186354 | B31: original | C31: ok | D31: ch | E31: 1 | F31: C164 | G31: 2 | H31: =G31*28 -> 56 | I31: 19 | J31: 3
A32: 7118641830+7173344320 | B32: original | C32: ok | D32: ch | G32: 1 | H32: =G32*28 -> 28
A33: 71186683+7173344320 | B33: original | C33: ok | D33: ch | E33: 1 | G33: 2 | H33: =G33*28 -> 56 | K33: add numbering
A34: 7118670020 | B34: original | C34: ok | D34: ch | E34: 1 | F34: C167 | G34: 2 | H34: =G34*28 -> 56 | I34: 19
A35: 7119101830+7274131020 | B35: original | C35: ok | D35: ch | G35: 1 | H35: =G35*28 -> 28
A36: 7119127830+7234894130A | B36: original | C36: ok | D36: ch | G36: 1 | H36: =G36*28 -> 28
A37: 7119131530 | B37: original | C37: ok | D37: ch | E37: 1 | G37: 3 | H37: =G37*28 -> 84 | I37: 19
A38: 7119140530+7119140640+72741359 | B38: original | C38: ok | D38: ch | G38: 2 | H38: =G38*28 -> 56
A39: 7119146730 | B39: original | C39: ok | D39: ch | E39: 1 | G39: 1 | H39: =G39*28 -> 28
A40: 7119163630 | B40: original | C40: ok | D40: ch | E40: 1 | G40: 4 | H40: =G40*28 -> 112
...

Sheet H248ClipPosition
A1: Указание за монтаж на клипс-холдър - H248 LHD
A2: name | B2: qtyx1 | C2: qtyx28 | D2: assembly_position | E2: status
A3: 7047052330D_DP | B3: 2 | C3: =B3*28 -> 56 | D3: Down
A4: 7047135830S_DP | B4: 1 | C4: =B4*28 -> 28 | D4: Side
A5: 7047186030D | B5: 14 | C5: =B5*28 -> 392 | D5: Down
A6: 7047186030D_DP | B6: 1 | C6: =B6*28 -> 28 | D6: Down
A7: 7047186030S | B7: 15 | C7: 448 | D7: Side
A8: 7047186030S_DP | B8: 3 | C8: =B8*28 -> 84 | D8: Side
A9: 7047186030U_DP | B9: 1 | C9: =B9*28 -> 28 | D9: Up
A10: 7052161430S_DP | B10: 1 | C10: =B10*28 -> 28 | D10: Side
A11: 7147882430D | B11: 1 | C11: =B11*28 -> 28 | D11: Down
A12: 7147882430D_DP | B12: 1 | C12: =B12*28 -> 28 | D12: Down
A13: 7147882430S | B13: 5 | C13: =B13*28 -> 140 | D13: Side
A14: 7247760930S_DP | B14: 1 | C14: =B14*28 -> 28 | D14: Side
A15: 7247761330U_DP | B15: 1 | C15: =B15*28 -> 28 | D15: Up
A16: 7247781230S_DP | B16: 1 | C16: =B16*28 -> 28 | D16: Side
A17: 7247781730U | B17: 2 | C17: =B17*28 -> 56 | D17: Up
A18: 72478572U_DP | B18: 1 | C18: =B18*28 -> 28 | D18: Up
A19: 7252726530D | B19: 2 | C19: =B19*28 -> 56 | D19: Down
... A31: 7252815130U | B31: 8 | C31: =B31*28 -> 224 | D31: Up

Sheet H248_SC35H
A1: Указание за монтаж на SC35H - H248 LHD
A2: name | B2: qtyx1 | C2: qtyx28 | D2: Zone | E2: status
A3: 71186354 | B3: 1 | C3: =Table2123[[#This Row],[qtyx1]]*28 -> 28 | D3: C164
A4: 71186683+7173344320 | B4: 2 | C4: =Table2123[[#This Row],[qtyx1]]*28 -> 56
A5: 7118670020 | B5: 1 | C5: =Table2123[[#This Row],[qtyx1]]*28 -> 28 | D5: C167
A6: 7119131530 | B6: 3 | C6: =Table2123[[#This Row],[qtyx1]]*28 -> 84
A7: 7119146730 | B7: 1 | C7: =Table2123[[#This Row],[qtyx1]]*28 -> 28
A8: 7119163630 | B8: 4 | C8: =Table2123[[#This Row],[qtyx1]]*28 -> 112
A9: 7119172930 | B9: 1 | C9: =Table2123[[#This Row],[qtyx1]]*28 -> 28
A10: 71191993 | B10: 1 | C10: =Table2123[[#This Row],[qtyx1]]*28 -> 28
A11: 7119639830 | B11: 1 | C11: =Table2123[[#This Row],[qtyx1]]*28 -> 28
A12: 71196401 | B12: 1 | C12: =Table2123[[#This Row],[qtyx1]]*28 -> 28
A13: 7119641970 | B13: 1 | C13: =Table2123[[#This Row],[qtyx1]]*28 -> 28
A14: 71196506 | B14: 1 | C14: =Table2123[[#This Row],[qtyx1]]*28 -> 28
A15: 7119668820 | B15: 1 | C15: =Table2123[[#This Row],[qtyx1]]*28 -> 28
A16: 71196714 | B16: 1 | C16: =Table2123[[#This Row],[qtyx1]]*28 -> 28
A17: 71781227 | B17: 1 | C17: =Table2123[[#This Row],[qtyx1]]*28 -> 28
... A19: 7183753630 | B19: 1 | C19: =Table2123[[#This Row],[qtyx1]]*28 -> 28
A20: 71884821+7134425740 | B20: 1 | C20: =Table2123[[#This Row],[qtyx1]]*28 -> 28
A21: 71897277 | B21: 1 | C21: =Table2123[[#This Row],[qtyx1]]*28 -> 28
A22: 71899503 | B22: 2 | C22: =Table2123[[#This Row],[qtyx1]]*28 -> 56
A23: 7189982830 | B23: 1 | C23: =Table2123[[#This Row],[qtyx1]]*28 -> 28
A24: 7198796290 | B24: 2 | C24: =Table2123[[#This Row],[qtyx1]]*28 -> 56
A25: 71988082 | B25: 1 | C25: =Table2123[[#This Row],[qtyx1]]*28 -> 28
A26: 7198916130 | B26: 1 | C26: =Table2123[[#This Row],[qtyx1]]*28 -> 28
A27: 71989162 | B27: 3 | C27: =Table2123[[#This Row],[qtyx1]]*28 -> 84
A28: 7198948560 | B28: 1 | C28: =Table2123[[#This Row],[qtyx1]]*28 -> 28
A29: 7223686530 | B29: 1 | C29: =Table2123[[#This Row],[qtyx1]]*28 -> 28
A30: 7278246930 | B30: 2 | C30: =Table2123[[#This Row],[qtyx1]]*28 -> 56
A31: 7289896430 | B31: 1 | C31: =Table2123[[#This Row],[qtyx1]]*28 -> 28
A32: 7297944190 | B32: 2 | C32: =Table2123[[#This Row],[qtyx1]]*28 -> 56
... A34: 7298949030 | B34: 1 | C34: =Table2123[[#This Row],[qtyx1]]*28 -> 28
A35: ASSY_123024542 | B35: 2 | C35: =Table2123[[#This Row],[qtyx1]]*28 -> 56
A36: ASSY_59Z006-T00D | B36: 1 | C36: =Table2123[[#This Row],[qtyx1]]*28 -> 28
A37: ASSY_59Z063DC0A | B37: 1 | C37: =Table2123[[#This Row],[qtyx1]]*28 -> 28
A38: ASSY_59Z063DC0C | B38: 1 | C38: =Table2123[[#This Row],[qtyx1]]*28 -> 28
A39: ASSY_CA288A15199XXX | B39: 2 | C39: =Table2123[[#This Row],[qtyx1]]*28 -> 56
A40: ASSY_CA288A25199XXX | B40: 2 | C40: =Table2123[[#This Row],[qtyx1]]*28 -> 56
A41: ASSY_E6Z017DC1C | B41: 1 | C41: =Table2123[[#This Row],[qtyx1]]*28 -> 28
A42: ASSY_PPI0001107+ASSY_PPI0001651+ASSY_PPI0001652 | B42: 4 | C42: =Table2123[[#This Row],[qtyx1]]*28 -> 112

Sheet h248LL
A1: job_order_id | B1: job_order_number | C1: ma_number | D1: name | E1: type_id | F1: batch_id | G1: quantity | H1: cut | I1: cnc | J1: assembly | K1: qc
A2: 1446 | B2: 262580 | C2: 10.21.77069A | D2: ASSY_AMZ040C00D | E2: 7 | F2: 19 | G2: 28 | H2: not passed | I2: not passed | J2: not passed | K2: not passed
A3: 1476 | B3: 262609 | C3: 10.21.75459A | D3: 7252785330 | E3: 25 | F3: 20 | G3: 112 | H3: not passed | I3: not passed | J3: not passed | K3: not passed
A4: 1470 | B4: 262603 | C4: 10.21.72843E | D4: 7147882430 | E4: 25 | F4: 20 | G4: 28 | H4: not passed | I4: not passed | J4: not passed | K4: not passed
A5: 1457 | B5: 262591 | C5: 10.21.77174A | D5: 7035990430 | E5: 7 | F5: 19 | G5: 56 | H5: not passed | I5: not passed | J5: not passed | K5: not passed
A6: 1449 | B6: 262583 | C6: 10.21.08826 | D6: 7047186030 | E6: 25 | F6: 19 | G6: 840 | H6: not passed | I6: not passed | J6: not passed | K6: not passed
A7: 1431 | B7: 262565 | C7: 10.21.73031A | D7: 7198796290 | E7: 7 | F7: 19 | G7: 56 | H7: not passed | I7: not passed | J7: not passed | K7: not passed
A8: 1469 | B8: 262602 | C8: 10.21.96572A | D8: 7052161430 | E8: 25 | F8: 20 | G8: 28 | H8: not passed | I8: not passed | J8: not passed | K8: not passed
A9: 1454 | B9: 262588 | C9: 10.21.96697 | D9: 7252785330 | E9: 25 | F9: 19 | G9: 364 | H9: not passed | I9: not passed | J9: not passed | K9: not passed
A10: 1444 | B10: 262578 | C10: 10.21.73076A | D10: ASSY_AMZ005000F/ASSY_AMZ005DC0F | E10: 7 | F10: 19 | G10: 28 | H10: not passed | I10: not passed | J10: not passed | K10: not passed
A11: 1442 | B11: 262576 | C11: 10.21.73067A | D11: ASSY_AMZ005DC0C | E11: 7 | F11: 19 | G11: 56 | H11: not passed | I11: not passed | J11: not passed | K11: not passed
A12: 1436 | B12: 262570 | C12: 10.21.76987A | D12: 72897304 | E12: 7 | F12: 19 | G12: 56 | H12: not passed | I12: not passed | J12: not passed | K12: not passed
A13: 1461 | B13: 262595 | C13: 10.21.77091A | D13: 7003756102 | E13: 7 | F13: 19 | G13: 28 | H13: not passed | I13: not passed | J13: not passed | K13: not passed
... A54: 1437 | B54: 262571 | C54: 10.21.76981A | D54: 7297944190 | E54: 7 | F54: 19 | G54: 56 | H54: not passed | I54: not passed | J54: not passed | K54: not passed

Sheet sa_mma_3
A1: pon | B1: family | C1: name | D1: ma | E1: qty
A2: I10123 | B2: ANTENNAS SPOT TAPE | C2: ASSY_123024501+ASSY_023024521 | E2: 10
A3: I10123 | B3: ANTENNAS SPOT TAPE | C3: WAVES_3 | D3: additional sheet | E3: 6
A4: I10123 | B4: ANTENNAS SPOT TAPE | C4: SB60 | E4: 1
A5: I10123 | B5: ANTENNAS SPOT TAPE | C5: SB40 | E5: 1
A6: I10123 | B6: ANTENNAS SPOT TAPE | C6: SB70 | E6: 2
A7: I10123 | B7: ANTENNAS SPOT TAPE | C7: SB90 | E7: 3
A8: I10123 | B8: ANTENNAS SPOT TAPE | C8: SB41 | E8: 1
A9: I10123 | B9: ANTENNAS SPOT TAPE | C9: SB50 | E9: 2
A10: I10123 | B10: ANTENNAS SPOT TAPE | C10: SA90_B | E10: 2
A11: I10123 | B11: ANTENNAS SPOT TAPE | C11: WIRE HOLDER U/D 6 | D11: additional sheet | E11: 4
A12: I10124 | B12: C-SUB02_A | C12: 2C09C4 | E12: 2
A13: I10124 | B13: C-SUB02_A | C13: 2C12C4 | E13: 3
A14: I10124 | B14: C-SUB02_A | C14: 2A12C4 | E14: 2
A15: I10124 | B15: C-SUB02_A | C15: 1A12D4 | E15: 1
A16: I10124 | B16: C-SUB02_A | C16: SC35H | E16: 6
A17: I10124 | B17: C-SUB02_A | C17: WRFT10 | E17: 1
A18: I10124 | B18: C-SUB02_A | C18: 3C1212C4 | E18: 1
A19: I10124 | B19: C-SUB02_A | C19: QL08 | E19: 1
A20: I10124 | B20: C-SUB02_A | C20: 2A09B4 | E20: 1
A21: I10124 | B21: C-SUB02_A | C21: 7298677930 | D21: 10.21.76980B | E21: 1
A22: I10124 | B22: C-SUB02_A | C22: 7298949030 | D22: 10.21.76979B | E22: 1
A23: I10124 | B23: C-SUB02_A | C23: 7298913330 | D23: 10.21.76963A | E23: 1
A24: I10124 | B24: C-SUB02_A | C24: ASSY_118021051 | D24: 10.21.76965A | E24: 2
A25: I10124 | B25: C-SUB02_A | C25: 7297913630 | E25: 1
A26: I10124 | B26: C-SUB02_A | C26: 7298948930 | D26: 10.21.72976A | E26: 1
A27: I10124 | B27: C-SUB02_A | C27: 7297914930 | E27: 1
A28: I10125 | B28: C-SUB23 | C28: SA90_B | E28: 1
A29: I10125 | B29: C-SUB23 | C29: WRFT10 | D29: 10.78.11960 | E29: 1
A30: I10125 | B30: C-SUB23 | C30: ASSY_123024501+ASSY_023024521 | E30: 4
A31: I10125 | B31: C-SUB23 | C31: 2C12C4 | E31: 1

Sheet pivot_sa_mma_3
G27: Sum of qty | H27: Column Labels
F28: ma | G28: Row Labels | H28: I10123 | I28: I10124 | J28: I10125 | K28: Grand Total
G29: 1A12D4 | I29: 1 | K29: 1
G30: 2A09B4 | I30: 1 | K30: 1
G31: 2A12C4 | I31: 2 | K31: 2
G32: 2C09C4 | I32: 2 | K32: 2
G33: 2C12C4 | I33: 3 | J33: 1 | K33: 4
G34: 3C1212C4 | I34: 1 | K34: 1
F35: 10.21.77088A | G35: 7297914930 | I35: 1 | K35: 1
F36: 10.21.76980B | G36: 7298677930 | I36: 1 | K36: 1
F37: 10.21.76963A | G37: 7298913330 | I37: 1 | K37: 1
F38: 10.21.72976A | G38: 7298948930 | I38: 1 | K38: 1
F39: 10.21.76979B | G39: 7298949030 | I39: 1 | K39: 1
F40: 10.21.76965A | G40: ASSY_118021051 | I40: 2 | K40: 2
F41: 10.21.97224 | G41: ASSY_123024501+ASSY_023024521 | H41: 10 | J41: 4 | K41: 14
G42: QL08 | I42: 1 | K42: 1
G43: SA90_B | H43: 2 | J43: 1 | K43: 3
G44: SB40 | H44: 1 | K44: 1
G45: SB41 | H45: 1 | K45: 1
G46: SB50 | H46: 2 | K46: 2
G47: SB60 | H47: 1 | K47: 1
G48: SB70 | H48: 2 | K48: 2
G49: SB90 | H49: 3 | K49: 3
G50: SC35H | I50: 6 | K50: 6
G51: WAVES_3 | H51: 6 | K51: 6
G52: WIRE HOLDER U/D 6 | H52: 4 | K52: 4
F53: 10.78.11960 | G53: WRFT10 | I53: 1 | J53: 1 | K53: 2
F54: 10.21.77146A | G54: 7297913630 | I54: 1 | K54: 1
G55: Grand Total | H55: 32 | I55: 26 | J55: 7 | K55: 65

Sheet batchs
A1: batch_id | B1: project_description | C1: is_active | D1: remark
A2: 1 | B2: I10017Rev01 - 15jb | C2: TRUE
A3: 2 | B3: I10017Rev01 - 15jb | C3: TRUE
A4: 3 | B4: I10017Rev01 - 15jb | C4: TRUE
A5: 4 | B5: I10017Rev01 - 15jb | C5: TRUE
A6: 5 | B6: I10017Rev01 - 15jb | C6: TRUE
A7: 6 | B7: I10017Rev01 - 15jb | C7: TRUE
A8: 7 | B8: rest 11 jb | C8: TRUE
A9: 8 | B9: engine H248 1 jb | C9: TRUE | D9: I10073
A10: 9 | B10: engine H248 1 jb | C10: TRUE | D10: I10073
A11: 10 | B11: main RHD+LHD H248 x 1jb | C11: TRUE | D11: I10074/5
A12: 11 | B12: main RHD+LHD H248 x 1jb | C12: TRUE | D12: I10074/5
A13: 12 | B13: main RHD+LHD H248 x 1jb | C13: TRUE | D13: I10074/5
A14: 13 | B14: engine H248 1 jb | C14: TRUE
A15: 14 | B15: main RHD+LHD H248 x 1jb | C15: TRUE | D15: I10074/5
A16: 66 | B16: test
A17: 15 | B17: I10017Rev01 - 15jb | C17: TRUE | D17: additional
A18: 16 | B18: I10017Rev01 - 15jb | C18: TRUE | D18: additional
A19: 17 | B19: main RHD+LHD H248 | C19: TRUE | D19: additional
A20: 99 | B20: test | C20: TRUE | D20: testing
A21: 18 | B21: Engine H248 16jb | C21: TRUE | D21: I10129
A22: 19 | B22: Main LHD H248 28jb | C22: FALSE | D22: I10130
A23: 20 | B23: Main LHD H248 28jb | C23: FALSE | D23: I10130

Sheet х248 миссинг
A3: 10.21.89505A | B3: 71186683+7173344320 | D3: CH | F3: FALSE | I3: 1 | J3: 73 | K3: 74 | L3: 65 | M3: WH | N3: POM | O3: TRUE | X3: 10 | Y3: =AI3*AH3 -> 4 | AB3: 95 | AC3: 16 | AD3: holder | AE3: TRUE | AH3: 4 | AI3: 1 | AJ3: 0 | AL3: 1
A4: 10.21.77121A | B4: 7118670020 | D4: CH | F4: FALSE | I4: 1 | J4: 50 | K4: 47 | L4: 51 | M4: RD | N4: POM | O4: TRUE | X4: 10 | Y4: =AI4*AH4 -> 4 | AB4: 176 | AC4: 10 | AD4: holder | AE4: TRUE | AH4: 4 | AI4: 1 | AJ4: 0
A5: 10.21.27914A | B5: 7119101830+7274131020A | D5: CH | F5: FALSE | I5: 1 | J5: 56 | K5: 48 | L5: 50 | M5: RD | N5: POM | O5: TRUE | X5: 10 | Y5: =AI5*AH5 -> 2 | AB5: 295 | AC5: 2 | AD5: holder | AH5: 2 | AI5: 1 | AJ5: 0
A6: 10.21.36860F | B6: 7119127830+7234894130A | D6: CH | F6: FALSE | I6: 1 | J6: 57 | K6: 48 | L6: 50 | M6: BK | N6: POM | O6: TRUE | V6: TRUE | X6: 10 | Y6: =AI6*AH6 -> 2 | AB6: 78 | AC6: 27 | AD6: holder | AH6: 2 | AI6: 1 | AJ6: 0
A7: 10.21.54168C | B7: 7119131530 | D7: CH | F7: FALSE | I7: 1 | J7: 42 | K7: 34 | L7: 42 | M7: BK | N7: POM | O7: TRUE | X7: 10 | Y7: =AI7*AH7 -> 6 | AB7: 93 | AC7: 26 | AD7: holder | AE7: TRUE | AH7: 6 | AI7: 1 | AJ7: 0
A8: 10.21.80751A | B8: 7119140530+7119140640+72741359A | D8: CH | F8: FALSE | I8: 1 | J8: 90 | K8: 50 | L8: 52 | M8: WH | N8: POM | O8: TRUE | V8: TRUE | X8: 10 | Y8: =AI8*AH8 -> 4 | AB8: 462 | AC8: 30 | AD8: holder | AH8: 4 | AI8: 1 | AJ8: 0
A9: 10.21.35002C | B9: 7119146730 | D9: CH | F9: FALSE | I9: 1 | J9: 42 | K9: 38 | L9: 42 | M9: BK | N9: POM | O9: TRUE | X9: 10 | Y9: =AI9*AH9 -> 2 | AB9: 116 | AC9: 13 | AD9: holder | AE9: TRUE | AH9: 2 | AI9: 1 | AJ9: 0
A10: 10.21.35003A | B10: 71191993 | C10: ? | D10: CH | F10: FALSE | I10: 1 | J10: 42 | K10: 35 | L10: 44 | M10: WH | N10: POM | O10: TRUE | X10: 10 | Y10: =AI10*AH10 -> 2 | AB10: 92 | AC10: 4 | AD10: holder | AE10: TRUE | AH10: 2 | AI10: 1 | AJ10: 0 | AL10: 1
A11: 10.21.77073A | B11: 71196180 | D11: CH | F11: FALSE | I11: 1 | J11: 40 | K11: 40 | L11: 52 | M11: WH | N11: POM | O11: TRUE | X11: 7 | Y11: =AI11*AH11 -> 1 | Z11: I10017Rev01 | AB11: 393 | AC11: 4 | AD11: holder | AH11: 1 | AI11: 1 | AJ11: 0
A12: 10.21.77045A | B12: 7183288530+7183288630+72742612 - 7119632530+7119632630+72742614A | D12: CH | F12: FALSE | I12: 1 | J12: 82 | K12: 77 | L12: 52 | M12: WH | N12: POM | O12: TRUE | Y12: =AI12*AH12 -> 0 | Z12: I10017Rev01 | AB12: 396 | AC12: 9 | AD12: holder | AH12: 1 | AJ12: 0
A13: 10.21.83680A | B13: 7119639830 | D13: CH | F13: FALSE | I13: 1 | J13: 46 | K13: 40 | L13: 48 | M13: BK | N13: POM | O13: TRUE | X13: 10 | Y13: =AI13*AH13 -> 2 | AB13: 286 | AC13: 4 | AD13: holder | AE13: TRUE | AH13: 2 | AI13: 1 | AJ13: 0
A14: 10.21.36271A | B14: 71196401 | D14: CH | F14: FALSE | I14: 1 | J14: 42 | K14: 39 | L14: 46 | M14: WH | N14: POM | O14: TRUE | X14: 10 | Y14: =AI14*AH14 -> 2 | AB14: 285 | AC14: 4 | AD14: holder | AE14: TRUE | AH14: 2 | AI14: 1 | AJ14: 0
A15: 10.21.83709A | B15: 7119641970 | D15: CH | F15: FALSE | I15: 1 | J15: 42 | K15: 36 | L15: 46 | M15: YE | N15: POM | O15: TRUE | X15: 10 | Y15: =AI15*AH15 -> 2 | AB15: 491 | AC15: 28 | AD15: holder | AE15: TRUE | AH15: 2 | AI15: 1 | AJ15: 0
A16: 10.21.47236A | B16: 71196506 | D16: CH | F16: FALSE | I16: 1 | J16: 42 | K16: 33 | L16: 47 | M16: WH | N16: POM | O16: TRUE | V16: TRUE | X16: 10 | Y16: =AI16*AH16 -> 2 | AB16: 76 | AC16: 28 | AD16: holder | AE16: TRUE | AH16: 2 | AI16: 1 | AJ16: 0
A17: 10.21.83671B | B17: 71196683+7173344320+X1PO2488 | D17: CH | F17: FALSE | I17: 1 | J17: 61 | K17: 50 | L17: 87 | M17: WH | N17: POM | O17: TRUE | Y17: =AI17*AH17 -> 0 | Z17: I10017Rev01 | AB17: 177 | AC17: 22 | AD17: holder | AE17: TRUE | AH17: 1 | AJ17: 0
A18: 10.21.77085A | B18: 7119668820 | D18: CH | F18: FALSE | I18: 1 | J18: 40 | K18: 37 | L18: 52 | M18: RD | N18: POM | O18: TRUE | X18: 10 | Y18: =AI18*AH18 -> 2 | AB18: 63 | AC18: 24 | AD18: holder | AE18: TRUE | AH18: 2 | AI18: 1 | AJ18: 0
A19: 10.21.73050A | B19: 7119670830+7274290770A | D19: CH | F19: FALSE | I19: 1 | J19: 55 | K19: 67 | L19: 52 | M19: YE | N19: POM | O19: TRUE | X19: 10 | Y19: =AI19*AH19 -> 6 | AB19: 401 | AC19: 13 | AD19: holder | AH19: 6 | AI19: 1 | AJ19: 0
A20: 10.21.80748A | B20: 71196714 | D20: CH | F20: FALSE | I20: 1 | J20: 45 | K20: 38 | L20: 59 | M20: WH | N20: POM | O20: TRUE | Y20: =AI20*AH20 -> 0 | Z20: I10017Rev01 | AB20: 388 | AC20: 14 | AD20: holder | AE20: TRUE | AH20: 2 | AJ20: 0
A21: 10.21.42593A | B21: 7119648630+7274171430A | D21: CH | F21: FALSE | I21: 1 | J21: 62 | K21: 67 | L21: 60 | M21: BK | N21: POM | O21: TRUE | X21: 10 | Y21: =AI21*AH21 -> 2 | AB21: 397 | AC21: 21 | AD21: holder | AH21: 2 | AI21: 1 | AJ21: 0
A22: 10.21.77076A | B22: 71781405 | D22: CH | F22: FALSE | I22: 1 | J22: 40 | K22: 39 | L22: 45 | M22: WH | N22: POM | O22: TRUE | Y22: =AI22*AH22 -> 0 | Z22: I10017Rev01 | AB22: 404 | AD22: holder | AE22: TRUE | AJ22: 0
A23: 10.21.72974A | B23: 7183288530+7183288630+72742612A | D23: CH | F23: FALSE | I23: 1 | J23: 82 | K23: 77 | L23: 52 | M23: WH | N23: POM | O23: TRUE | X23: 10 | Y23: =AI23*AH23 -> 4 | AB23: 298 | AC23: 3 | AD23: holder | AH23: 4 | AI23: 1 | AJ23: 0
A24: 10.21.77049A | B24: 7185173030+7185173130+72742608A | D24: CH | F24: FALSE | I24: 1 | J24: 92 | K24: 75 | L24: 52 | M24: WH | N24: POM | O24: TRUE | X24: 10 | Y24: =AI24*AH24 -> 1 | AB24: 140 | AC24: 25 | AD24: holder | AH24: 1 | AI24: 1 | AJ24: 0
A25: 10.21.42674D | B25: 7187903970+7187904070+7274060970A | D25: CH | F25: FALSE | I25: 1 | J25: 92 | K25: 68 | L25: 55 | M25: YE | N25: POM | O25: TRUE | X25: 11 | Y25: =AI25*AH25 -> 2 | AB25: 180 | AC25: 16 | AD25: holder | AH25: 2 | AI25: 1 | AJ25: 0
A26: 10.21.72978A | B26: 71884821+7134425740 | D26: CH | F26: FALSE | I26: 1 | J26: 51 | K26: 51 | L26: 66 | M26: WH | N26: POM | O26: TRUE | X26: 10 | Y26: =AI26*AH26 -> 2 | AB26: 94 | AC26: 17 | AD26: holder | AE26: TRUE | AH26: 2 | AI26: 1 | AJ26: 0
A27: 10.21.83656D | B27: 7188503730+7174152230A(7177097330) | D27: CH | F27: FALSE | I27: 1 | J27: 84 | K27: 78 | L27: 49 | M27: BK | N27: POM | O27: TRUE | X27: 10 | Y27: =AI27*AH27 -> 2 | AB27: 234 | AC27: 23 | AD27: holder | AH27: 2 | AI27: 1 | AJ27: 0 | AK27: Y4317
A28: 10.21.83657E | B28: 7188503730+7174152230A(7177097330) | D28: CH | F28: FALSE | I28: 1 | J28: 84 | K28: 78 | L28: 49 | M28: BK | N28: POM | O28: TRUE | X28: 10 | Y28: =AI28*AH28 -> 2 | AB28: 205 | AC28: 8 | AD28: holder | AH28: 2 | AI28: 1 | AJ28: 0 | AK28: Y4318
A29: 10.21.35851A | B29: 7189663170 | D29: CH | F29: FALSE | I29: 1 | J29: 44 | K29: 36 | L29: 46 | M29: YE | N29: POM | O29: TRUE | X29: 10 | Y29: =AI29*AH29 -> 4 | AB29: 213 | AC29: 8 | AD29: holder | AH29: 4 | AI29: 1 | AJ29: 0
A30: 10.21.76941A | B30: 7189811530+7289811830+72741554A | D30: CH | F30: FALSE | I30: 1 | J30: 124 | K30: 76 | L30: 62 | M30: WH | N30: POM | O30: TRUE | X30: 10 | Y30: =AI30*AH30 -> 2 | AB30: 296 | AC30: 2 | AD30: holder | AH30: 2 | AI30: 1 | AJ30: 0
A31: 10.21.28074A | B31: 71899503 | D31: CH | F31: FALSE | I31: 1 | J31: 40 | K31: 32 | L31: 47 | M31: WH | N31: POM | O31: TRUE | X31: 10 | Y31: =AI31*AH31 -> 4 | AB31: 129 | AC31: 8 | AD31: holder | AE31: TRUE | AH31: 4 | AI31: 1 | AJ31: 0
A32: 10.21.76956B | B32: 7189982830 | D32: CH | F32: FALSE | I32: 1 | J32: 42 | K32: 42 | L32: 51 | M32: BK | N32: POM | O32: TRUE | X32: 10 | Y32: =AI32*AH32 -> 2 | AB32: 453 | AC32: 7 | AD32: holder | AE32: TRUE | AH32: 2 | AI32: 1 | AJ32: 0
A33: 10.21.47066D | B33: 7189668330+7274135020A | D33: CH | F33: FALSE | I33: 1 | J33: 68 | K33: 65 | L33: 50 | M33: RD | N33: POM | O33: TRUE | V33: TRUE | X33: 11 | Y33: =AI33*AH33 -> 2 | AB33: 101 | AC33: 12 | AD33: holder | AH33: 2 | AI33: 1 | AJ33: 0
A34: 10.21.47047D | B34: 7189668330+7274136090A | D34: CH | F34: FALSE | I34: 1 | J34: 68 | K34: 65 | L34: 52 | M34: BL | N34: POM | O34: TRUE | V34: TRUE | X34: 11 | Y34: =AI34*AH34 -> 2 | AB34: 101 | AC34: 12 | AD34: holder | AH34: 2 | AI34: 1 | AJ34: 0
A35: 10.21.47065D | B35: 7189730210+7274146260A | D35: CH | F35: FALSE | I35: 1 | J35: 68 | K35: 65 | L35: 50 | M35: GN | N35: POM | O35: TRUE | V35: TRUE | X35: 11 | Y35: =AI35*AH35 -> 2 | AB35: 97 | AC35: 13 | AD35: holder | AH35: 2 | AI35: 1 | AJ35: 0
A36: 10.21.96493A | B36: 71980943 | D36: CH | F36: FALSE | I36: 1 | J36: 42 | K36: 42 | L36: 46 | M36: WH | N36: POM | O36: TRUE | Y36: =AI36*AH36 -> 0 | Z36: I10017Rev01 | AB36: 506 | AC36: 7 | AD36: holder | AE36: TRUE | AJ36: 0
A37: 10.21.80753C | B37: 7198277430+7198277530+72741954A | D37: CH | F37: FALSE | I37: 1 | J37: 100 | K37: 57 | L37: 53 | M37: WH | N37: POM | O37: TRUE | X37: 10 | Y37: =AI37*AH37 -> 2 | AB37: 605 83 | AC37: 31 17 | AD37: holder | AH37: 2 | AI37: 1 | AJ37: 0
A38: 10.21.77125A | B38: 71986562 | D38: CH | F38: FALSE | I38: 1 | J38: 44 | K38: 41 | L38: 48 | M38: WH | N38: POM | O38: TRUE | X38: 10 | Y38: =AI38*AH38 -> 2 | AB38: 244 | AC38: 32 | AD38: holder | AE38: TRUE | AH38: 2 | AI38: 1 | AJ38: 0
A39: 10.21.83630A | B39: 7198762530+7198600430+7274261190A | D39: CH | F39: FALSE | I39: 1 | J39: 100 | K39: 75 | L39: 60 | M39: BL | N39: POM | O39: TRUE | X39: 10 | Y39: =AI39*AH39 -> 4 | AB39: 247, 243 | AC39: 32 | AD39: holder | AH39: 4 | AI39: 1 | AJ39: 0
A40: 10.21.80775B | B40: 7198774930+7198947430+72742908A | D40: CH | F40: FALSE | I40: 1 | J40: 106 | K40: 74 | L40: 66 | M40: WH | N40: POM | O40: TRUE | X40: 10 | Y40: =AI40*AH40 -> 4 | AB40: 189 | AC40: 12 | AD40: holder | AH40: 4 | AI40: 1 | AJ40: 0
A41: 10.21.80733A | B41: 71987958 | D41: CH | F41: FALSE | I41: 1 | J41: 80 | K41: 45 | L41: 53 | M41: WH | N41: POM | O41: TRUE | X41: 10 | Y41: =AI41*AH41 -> 4 | AB41: 425 | AC41: 8 | AD41: holder | AH41: 4 | AI41: 1 | AJ41: 0 | AN41: cnc
A42: 10.21.73031A | B42: 7198796290 | D42: CH | F42: FALSE | I42: 1 | J42: 41 | K42: 41 | L42: 42 | M42: BL | N42: POM | O42: TRUE | X42: 10 | Y42: =AI42*AH42 -> 4 | AB42: 386 | AC42: 14 | AD42: holder | AE42: TRUE | AH42: 4 | AI42: 1 | AJ42: 0
...

Sheet dispach 0302026
C2: H248 Main LHD/RHD
C3: MA | D3: YPN | E3: QTY, pcs | F3: price offer
C4: 10.21.54326E | D4: 7047186030D_DP | E4: 1 | F4: I10074
C5: 10.21.72843E | D5: 7147882430D_DP | E5: 1 | F5: I10074
C6: 10.21.89505A | D6: 71186683+7173344320 | E6: 1 | F6: I10074
C7: 10.21.96568A | D7: 7289982670 | E7: 1 | F7: I10074
C8: 10.21.96568A | D8: 7289982670 | E8: 1 | F8: I10075
C9: 10.21.96573A | D9: 7287547130 | E9: 1 | F9: I10074
C10: 10.21.96573A | D10: 7287547130 | E10: 1 | F10: I10075
C11: 10.21.96570A | D11: 7035990930 | E11: 1 | F11: I10074
C12: 10.21.96570A | D12: 7035990930 | E12: 1 | F12: I10075
C13: За Тодор Стоянов
C19: 11 JB MAIN I9986 7000465161-1
C20: MA | D20: YPN | E20: QTY, pcs | F20: price offer
F21: I9986
F22: I9986
F23: I9986
F24: I9986
F25: I9986
F26: I9986
F27: I9986
B29: b | C29: 15 JB MAIN / I10017Rev01 7000474804-1
C30: MA | D30: YPN | E30: QTY, pcs | F30: price offer
B31: 0 | F31: I10017Rev01
B32: 1 | F32: I10017Rev01
B33: 1 | F33: I10017Rev01
B34: 1 | F34: I10017Rev01
B35: 2 | F35: I10017Rev01
B36: 2 | F36: I10017Rev01
B37: 2 | F37: I10017Rev01
C44: Стоковата е разписана!
C45: Стоковата е разписана!

Sheet dispach 29062026
C2: H248 Main/Engine LHD/RHD 2 JB
C3: MA | D3: YPN | E3: QTY, pcs | F3: price offer
C4: 10.21.83679A | D4: 7119172930 | E4: 1 | F4: I10074
C5: 10.21.83679A | D5: 7119172930 | E5: 1 | F5: I10075
C6: 10.21.96563A | D6: 7035964930 | E6: 2 | F6: I10074
C7: 10.21.96563A | D7: 7035964930 | E7: 2 | F7: I10075
C8: 10.21.96563A | D8: 7035964930 | E8: 1 | F8: I10073
C9: 10.21.35334A | D9: 7118641830+7173344320 | E9: 1 | F9: I10074
C10: 10.21.35334A | D10: 7118641830+7173344320 | E10: 1 | F10: I10075
C11: 10.21.77068A | D11: ASSY_AMZ040C00C | E11: 1 | F11: I10075
C12: 10.21.28074A | D12: 71899503 | E12: 1 | F12: I10074
C13: 10.21.28074A | D13: 71899503 | E13: 1 | F13: I10075
C14: 10.21.54489A | D14: 71897277 | E14: 1 | F14: I10074
C15: 10.21.54489A | D15: 71897277 | E15: 1 | F15: I10075
C16: 10.21.76983B | D16: 7252815130 | E16: 10 | F16: I10074
C17: 10.21.77038A | D17: ASSY_CA288A15199XXX | E17: 1 | F17: I10074
C18: 10.21.50179G | D18: 7187903970+7187904070 | E18: 1 | F18: I10074
C20: 11 JB MAIN I9986 7000465161-1
C21: MA | D21: YPN | E21: QTY, pcs | F21: price offer
C22: 10.21.72968A | D22: 7075236930 | E22: 1 | F22: I9986
C23: 10.21.80751A | D23: 7119140530+7119140640+72741359A | E23: 1 | F23: I9986
C24: 10.21.35003A | D24: 71191993 | E24: 2 | F24: I9986
C25: 10.21.77073A | D25: 71196180 | E25: 1 | F25: I9986
C26: 10.21.47236A | D26: 71196506 | E26: 1 | F26: I9986
C27: 10.21.73076A | D27: ASSY_AMZ005000F/ASSY_AMZ005DC0F | E27: 1 | F27: I9986
C28: 10.21.77089A | D28: ASSY_D4K2RE1D5A5BDC/ASSY_D4K2RE1D5A5B | E28: 1 | F28: I9986
B30: b | C30: 15 JB MAIN / I10017Rev01 7000474804-1
C31: MA | D31: YPN | E31: QTY, pcs | F31: price offer
B32: 0 | C32: 10.21.83692A | D32: 7198600430 | E32: 14 | F32: I10017Rev01
B33: 1 | C33: 10.21.77190A | D33: 7118673890+7173344320 | E33: 7 | F33: I10017Rev01
B34: 1 | C34: 10.21.76985A | D34: 7298808730 | E34: 7 | F34: I10017Rev01
B35: 1 | C35: 10.21.83758A | D35: 7198809140+7274268930A | E35: 7 | F35: I10017Rev01
B36: 2 | C36: 10.21.80751A | D36: 7119140530+7119140640+72741359A | E36: 14 | F36: I10017Rev01
B37: 2 | C37: 10.21.77067A | D37: ASSY_59Z006T00C | E37: 7 | F37: I10017Rev01
B38: 2 | C38: 10.21.77151A | D38: ASSY_E6Z017DC1C | E38: 7 | F38: I10017Rev01
C45: Стоковата е разписана!
C46: Стоковата е разписана!

Sheet product_list (2)
A1: MA_Number | B1: Product_Name | C1: type_code | D1: Description | E1: Is_Assembly | F1: parent_ma | G1: Part_Number | H1: Part_Qty | I1: Part_Length | J1: Part_Width | K1: Part_Height | L1: color_code | M1: material_code | N1: process_cut | O1: process_mill | P1: Assembly_Order | Q1: batch_id | R1: qty | S1: price_offer_num
A2: 10.21.1111 | B2: 7283 1111 30 | C2: pch | D2: STR1 | E2: FALSE | H2: 1111 | I2: 1111 | J2: 1111 | K2: 1111 | L2: WH | M2: POM | O2: TRUE | Q2: 3 | R2: 10 | S2: 1000
A3: 10.21.2222 | B3: 7283 2222 30 | C3: ch | D3: STR | E3: FALSE | H3: 1 | I3: 666 | J3: 667 | K3: 668 | L3: BK | M3: BR | N3: TRUE | Q3: 3 | R3: 11 | S3: 1000
A4: 10.21.3333 | B4: 7283 2222 30 | C4: ch | D4: STR | E4: TRUE | H4: 2 | I4: 44 | J4: 44 | K4: 44 | L4: BK | M4: BR | N4: TRUE | Q4: 3 | R4: 12 | S4: 1001
B5: 7283 2222 30 | C5: ch | D5: STR | F5: 10.21.3333 | G5: 10.21.3333-1 | H5: 1 | I5: 55 | J5: 55 | K5: 55 | L5: BK | M5: BR | N5: TRUE | Q5: 3 | R5: 13 | S5: 1001
B6: 7283 2222 30 | C6: ch | D6: STR | F6: 10.21.3333 | G6: 10.21.3333-2 | H6: 1 | I6: 66 | J6: 66 | K6: 66 | L6: BK | M6: BR | N6: TRUE | Q6: 3 | R6: 14 | S6: 1005
A7: 10.21.4444 | B7: 7283 2222 30 | C7: pch | D7: STR | E7: FALSE | H7: 1 | I7: 10 | J7: 20 | K7: 30 | L7: BK | M7: BR | N7: TRUE | Q7: 3 | R7: 15 | S7: 1005
A8: 10.21.5555 | B8: 7283 2222 30 | C8: pch | D8: STR | E8: FALSE | H8: 1 | I8: 10 | J8: 20 | K8: 30 | L8: BL | M8: BR | N8: TRUE | Q8: 3 | R8: 16 | S8: 1005
A9: 10.21.6666 | B9: 7283 2222 30 | C9: pch | D9: STR | E9: FALSE | H9: 1 | I9: 10 | J9: 20 | K9: 30 | L9: BK | M9: BR | N9: TRUE | Q9: 3 | R9: 17 | S9: 1005
A10: 10.21.7777 | B10: 7283 2222 30 | C10: ch | D10: STR | E10: TRUE | H10: 2 | I10: 50 | J10: 50 | K10: 50 | L10: BK | M10: BR | N10: TRUE | Q10: 3 | R10: 18 | S10: 1005
B11: 7283 2222 30 | C11: ch | D11: STR | F11: 10.21.7777 | G11: 10.21.7777-1 | H11: 1 | I11: 30 | J11: 30 | K11: 30 | L11: BK | M11: BR | N11: TRUE | Q11: 3 | R11: 19 | S11: 1005
B12: 7283 2222 30 | C12: ch | D12: STR | F12: 10.21.7777 | G12: 10.21.7777-2 | H12: 1 | I12: 20 | J12: 20 | K12: 20 | L12: BK | M12: BR | N12: TRUE | Q12: 3 | R12: 20 | S12: 1005
A13: 10.21.8888 | B13: 7283 2222 30 | C13: ch | D13: STR | E13: TRUE | H13: 2 | I13: 50 | J13: 50 | K13: 50 | L13: BK | M13: BR | N13: TRUE | Q13: 3 | R13: 21 | S13: 1005
B14: 7283 2222 30 | C14: ch | D14: STR | F14: 10.21.8888 | G14: 10.21.8888-1 | H14: 2 | I14: 30 | J14: 30 | K14: 30 | L14: BK | M14: BR | N14: TRUE | Q14: 3 | R14: 22 | S14: 1005
B15: 7283 2222 30 | C15: ch | D15: STR | F15: 10.21.8888 | G15: 10.21.8888-2 | H15: 2 | I15: 20 | J15: 20 | K15: 20 | L15: BK | M15: BR | N15: TRUE | Q15: 3 | R15: 23 | S15: 1005
A16: 10.21.9999 | B16: 7283 1111 30 | C16: ch | D16: STR | E16: FALSE | H16: 1 | I16: 50 | J16: 50 | K16: 50 | L16: BK | M16: BR | N16: TRUE | Q16: 3 | R16: 24 | S16: 1005
A17: 10.21.1212 | B17: 7283554430 | C17: ch | D17: STR | E17: FALSE | H17: 1 | I17: 66 | J17: 67 | K17: 68 | L17: WH | M17: POM | N17: TRUE | Q17: 3 | R17: 888

Sheet type_list
A1: type_code | B1: type_name | C1: description | D1: created_at | E1: updated_at | F1: created_by
A2: CH | B2: connector holder
A3: PCH | B3: pneumatic connector holder
A4: FORK | B4: JB fork
A5: CLIP H | B5: clip holder
A6: PCC | B6: pneumatic connector clip

Sheet price_offer_list
A1: price_offer_num | B1: created_at | C1: updated_at | D1: created_by
A2: I10017Rev01
A3: I9987
A4: I10129
A5: I10130

Sheet color_list
A1: color_code | B1: color_name | C1: color_name_bg | D1: rgb_value | E1: pantone_code | F1: is_active | G1: created_at | H1: updated_at | I1: created_by
A2: WH | B2: white | C2: БЯЛ | F2: TRUE
A3: BK | B3: black | C3: ЧЕРЕН | F3: TRUE
A4: BL | B4: blue | C4: СИН | F4: TRUE
A5: BN | B5: brown | C5: КАФЯВ | F5: TRUE
A6: GN | B6: green | C6: ЗЕЛЕН | F6: TRUE
A7: RD | B7: red | C7: ЧЕРВЕН | F7: TRUE
A8: YE | B8: yellow | C8: ЖЪЛТ | F8: TRUE
A9: GR | B9: gray | C9: СИВ | F9: TRUE

Sheet material_list
A1: material_code | B1: material_name | C1: material_name_bg | D1: category | E1: density_kg_per_m3 | F1: tensile_strength_mpa | G1: cost_per_kg | H1: is_active | I1: created_at | J1: updated_at | K1: created_by
A2: STL | B2: Steel | C2: СТОМАНА | H2: TRUE
A3: POM | B3: Derlin | C3: ДЕЛРИН | H3: TRUE
A4: BR | B4: Brass | C4: МЕСИНГ | H4: TRUE
A5: AL | B5: Aluminium | C5: АЛУМИНИЙ | H5: TRUE
A6: SS | B6: Stainless steel | C6: НЕРЪЖДАВЕЙКА | H6: TRUE

Sheet product_projects
A1: product_ma | B1: project_name
A2: 10.21.80758A | B2: MMA
A3: 10.21.72966C | B3: MMA
A4: 10.21.72968A | B4: MMA
A5: 10.21.83798A | B5: MMA
A6: 10.21.35131A | B6: MMA
A7: 10.21.35334A | B7: MMA
A8: 10.21.89505A | B8: MMA
A9: 10.21.77121A | B9: MMA
A10: 10.21.27914A | B10: MMA
A11: 10.21.36860F | B11: MMA
A12: 10.21.54168C | B12: MMA
... A207: 10.21.72971A | B207: MMA

Sheet product_families
A1: product_ma | B1: family_name
A2: 10.21.80758A | B2: main
A3: 10.21.72966C | B3: main
A4: 10.21.72968A | B4: main
A5: 10.21.83798A | B5: main
A6: 10.21.35131A | B6: main
A7: 10.21.35334A | B7: main
A8: 10.21.89505A | B8: main
A9: 10.21.77121A | B9: main
A10: 10.21.27914A | B10: main
A11: 10.21.36860F | B11: main
A12: 10.21.54168C | B12: main
... A213: 10.21.72971A | B213: main

Sheet barcode
B1: 0 | C1: ="*"&B1&"*" -> *0*
B2: 261493 | C2: ="*"&B2&"*" -> *261493*
B3: 261494 | C3: ="*"&B3&"*" -> *261494*
B4: 261495 | C4: ="*"&B4&"*" -> *261495*
B5: 261496 | C5: ="*"&B5&"*" -> *261496*
B6: 261497 | C6: ="*"&B6&"*" -> *261497*
B7: 261498 | C7: ="*"&B7&"*" -> *261498*
B8: 261499 | C8: ="*"&B8&"*" -> *261499*
B9: 261500 | C9: ="*"&B9&"*" -> *261500*
B10: 261501 | C10: ="*"&B10&"*" -> *261501*
B11: 261502 | C11: ="*"&B11&"*" -> *261502*
B12: 261503 | C12: ="*"&B12&"*" -> *261503*
B13: 261504 | C13: ="*"&B13&"*" -> *261504*
B14: 261505 | C14: ="*"&B14&"*" -> *261505*
B15: 261506 | C15: ="*"&B15&"*" -> *261506*
... B97: 261588 | C97: ="*"&B97&"*" -> *261588*

Sheet sps calc
A1: X | B1: =J9+J10*2+J12 -> 63
A2: Y | B2: =J9+J11*2+J10*2+J13 -> 79
A3: Z | B3: =J14+J15+J16 -> 65
A4: V | B4: =B1*B2*B3/1000 -> 323.505
E7: =IF(B4<100,"S",IF(B4<225,"M",IF(B4<550,"L",IF(B4<1150,"XL",IF(B4>1150,"XXL",FALSE))))) -> L | T7: j
E8: =IF(J14<15, "SIMPLE", IF(J14<30, "MEDIUM", "COMPLEX")) -> COMPLEX
E9: =IF(AND(E7="S", E8="SIMPLE"),"A",IF(AND(E7="S",E8="MEDIUM"), "F", IF(AND(E7="M",E8="SIMPLE"), "B", IF(AND(E7="M",E8="MEDIUM"), "G", IF(AND(E7="M",E8="COMPLEX"), "L", IF(AND(E7="L",E8="SIMPLE"), "C", IF(AND(E7="L",E8="MEDIUM"), "H", IF(AND(E7="L",E8="COMPLEX"), "M", IF(AND(E7="XL",E8="SIMPLE"), "D", IF(AND(E7="XL",E8="MEDIUM"), "I", IF(AND(E7="XL",E8="COMPLEX"), "N", IF(AND(E7="XXL",E8="SIMPLE"), "E", IF(AND(E7="XXL",E8="MEDIUM"), "G", IF(AND(E7="XXL",E8="COMPLEX"), "O", FALSE)))))))))))))) -> M | I9: j left or right | J9: 5 | M9: j | N9: e | AE9: e | AF9: j
I10: lock | J10: 9
I11: ear | J11: 13
I12: x conn | J12: 40
I13: y conn | J13: 30 | AB13: lock
I14: z conn | J14: 30
I15: jig bottom | J15: 10
I16: ejector | J16: 25 | V16: y
A18: YPN | B18: PO | C18: leter
A19: 7289724330 | B19: I10061 | C19: op16
A20: 7298186930 | B20: I10061 | C20: h | T20: j
A21: 72888941 | B21: I10061 | C21: l
A22: 7278442030 | B22: I10061 | C22: h
A23: 72985208 | B23: I10061 | C23: op16 | AI23: A | AJ23: B | AK23: C | AL23: D | AM23: E | AO23: F | AP23: G | AQ23: H | AR23: I | AS23: J | AT23: K | AU23: L | AV23: M | AW23: N | AX23: O
A24: 7298150830 | B24: I10061 | C24: op16
A25: 7198460730 | B25: I10061 | C25: h
A26: 7298108030 | B26: I10061 | C26: op16
A27: 7298154930 | B27: I10061 | C27: l
B28: I10061
A29: 7289724330 | B29: I10061 | C29: op16
A30: 7278271940 | B30: I10061 | C30: op16
A31: 7298186930 | B31: I10061 | C31: h
A32: 72888941 | B32: I10061 | C32: l
A33: 7278442030 | B33: I10061 | C33: h
A34: 72985208 | B34: I10061 | C34: op16
A35: 7298108030 | B35: I10061 | C35: op16
A36: 7198460730 | B36: I10061 | C36: h
A37: 7298154930 | B37: I10061 | C37: l
A38: 7298150830 | B38: I10061 | C38: op16
A39: 71191147 | B39: I10061 | C39: op16
B40: I10061
A41: 7187090590 | B41: I10061 | C41: op16
A42: 7277015590 | B42: I10061 | C42: m
A43: 7187090560 | B43: I10061 | C43: op16
...

Sheet Sheet3
A1: YPN | B1: PO | C1: leter | D1: remark
A2: 7289724330 | B2: I10061
A3: 7298186930 | B3: I10061
A4: 72888941 | B4: I10061
A5: 7278442030 | B5: I10061
A6: 72985208 | B6: I10061
A7: 7298150830 | B7: I10061
A8: 7198460730 | B8: I10061
A9: 7298108030 | B9: I10061
A10: 7298154930 | B10: I10061
B11: I10061
A12: 7289724330 | B12: I10061
A13: 7278271940 | B13: I10061
A14: 7298186930 | B14: I10061
A15: 72888941 | B15: I10061
A16: 7278442030 | B16: I10061
A17: 72985208 | B17: I10061
A18: 7298108030 | B18: I10061
A19: 7198460730 | B19: I10061
A20: 7298154930 | B20: I10061
A21: 7298150830 | B21: I10061
A22: 71191147 | B22: I10061
B23: I10061
A24: 7187090590 | B24: I10061
A25: 7277015590 | B25: I10061
A26: 7187090560 | B26: I10061
A27: 71870905 | B27: I10061
A28: 71983904 | B28: I10061
A29: 7287741830 | B29: I10061
A30: 7288907230 | B30: I10061
A31: 7298227830 | B31: I10061
A32: 7298227830 | B32: I10061
A33: 7298593130 | B33: I10061
A34: 7298593130 | B34: I10061
A35: 7285207290 | B35: I10061
... A37: 71870905 | B37: I10061
B38: I10061
A39: 7298228030 | B39: I10061
A40: 7288907230 | B40: I10061
A41: 7298228030 | B41: I10061
...

Sheet pch
A1: ypn | B1: trim | C1: check equal | D1: check string | E1: type | F1: ma_final | G1: note
A2: 70521459 | B2: =TRIM(Table4[[#This Row],[ypn]]) -> 70521459 | C2: =Table4[[#This Row],[ypn]]=Table4[[#This Row],[trim]] -> FALSE | D2: =Table4[[#This Row],[ypn]]*1 -> 70521459 | E2: =TYPE(Table4[[#This Row],[ypn]]) -> 1
A3: 71186354 | B3: =TRIM(Table4[[#This Row],[ypn]]) -> 71186354 | C3: =Table4[[#This Row],[ypn]]=Table4[[#This Row],[trim]] -> FALSE | D3: =Table4[[#This Row],[ypn]]*1 -> 71186354 | E3: =TYPE(Table4[[#This Row],[ypn]]) -> 1 | F3: 10.21.43811A
A4: 71191993 | B4: =TRIM(Table4[[#This Row],[ypn]]) -> 71191993 | C4: =Table4[[#This Row],[ypn]]=Table4[[#This Row],[trim]] -> FALSE | D4: =Table4[[#This Row],[ypn]]*1 -> 71191993 | E4: =TYPE(Table4[[#This Row],[ypn]]) -> 1 | F4: 10.21.38043A
A5: 71196180 | B5: =TRIM(Table4[[#This Row],[ypn]]) -> 71196180 | C5: =Table4[[#This Row],[ypn]]=Table4[[#This Row],[trim]] -> FALSE | D5: =Table4[[#This Row],[ypn]]*1 -> 71196180 | E5: =TYPE(Table4[[#This Row],[ypn]]) -> 1 | F5: 10.21.77371A
A6: 71196350 | B6: =TRIM(Table4[[#This Row],[ypn]]) -> 71196350 | C6: =Table4[[#This Row],[ypn]]=Table4[[#This Row],[trim]] -> FALSE | D6: =Table4[[#This Row],[ypn]]*1 -> 71196350 | E6: =TYPE(Table4[[#This Row],[ypn]]) -> 1 | F6: 10.21.37931A
A7: 71196401 | B7: =TRIM(Table4[[#This Row],[ypn]]) -> 71196401 | C7: =Table4[[#This Row],[ypn]]=Table4[[#This Row],[trim]] -> FALSE | D7: =Table4[[#This Row],[ypn]]*1 -> 71196401 | E7: =TYPE(Table4[[#This Row],[ypn]]) -> 1 | F7: 10.21.38690A
A8: 71196506 | B8: =TRIM(Table4[[#This Row],[ypn]]) -> 71196506 | C8: =Table4[[#This Row],[ypn]]=Table4[[#This Row],[trim]] -> FALSE | D8: =Table4[[#This Row],[ypn]]*1 -> 71196506 | E8: =TYPE(Table4[[#This Row],[ypn]]) -> 1 | F8: 10.21.77048A
A9: 71196714 | B9: =TRIM(Table4[[#This Row],[ypn]]) -> 71196714 | C9: =Table4[[#This Row],[ypn]]=Table4[[#This Row],[trim]] -> FALSE | D9: =Table4[[#This Row],[ypn]]*1 -> 71196714 | E9: =TYPE(Table4[[#This Row],[ypn]]) -> 1 | F9: 10.21.80749
A10: 71781227 | B10: =TRIM(Table4[[#This Row],[ypn]]) -> 71781227 | C10: =Table4[[#This Row],[ypn]]=Table4[[#This Row],[trim]] -> FALSE | D10: =Table4[[#This Row],[ypn]]*1 -> 71781227 | E10: =TYPE(Table4[[#This Row],[ypn]]) -> 1 | F10: 10.21.84407
A11: 71781405 | B11: =TRIM(Table4[[#This Row],[ypn]]) -> 71781405 | C11: =Table4[[#This Row],[ypn]]=Table4[[#This Row],[trim]] -> FALSE | D11: =Table4[[#This Row],[ypn]]*1 -> 71781405 | E11: =TYPE(Table4[[#This Row],[ypn]]) -> 1 | F11: 10.21.77033
A12: 71782472 | B12: =TRIM(Table4[[#This Row],[ypn]]) -> 71782472 | C12: =Table4[[#This Row],[ypn]]=Table4[[#This Row],[trim]] -> FALSE | D12: =Table4[[#This Row],[ypn]]*1 -> 71782472 | E12: =TYPE(Table4[[#This Row],[ypn]]) -> 1 | F12: 10.21.80724
A13: 71834835 | B13: =TRIM(Table4[[#This Row],[ypn]]) -> 71834835 | C13: =Table4[[#This Row],[ypn]]=Table4[[#This Row],[trim]] -> FALSE | D13: =Table4[[#This Row],[ypn]]*1 -> 71834835 | E13: =TYPE(Table4[[#This Row],[ypn]]) -> 1 | F13: 10.21.63723C
A14: 71897277 | B14: =TRIM(Table4[[#This Row],[ypn]]) -> 71897277 | C14: =Table4[[#This Row],[ypn]]=Table4[[#This Row],[trim]] -> FALSE | D14: =Table4[[#This Row],[ypn]]*1 -> 71897277 | E14: =TYPE(Table4[[#This Row],[ypn]]) -> 1 | F14: 10.21.39390A
A15: 71899503 | B15: =TRIM(Table4[[#This Row],[ypn]]) -> 71899503 | C15: =Table4[[#This Row],[ypn]]=Table4[[#This Row],[trim]] -> FALSE | D15: =Table4[[#This Row],[ypn]]*1 -> 71899503 | E15: =TYPE(Table4[[#This Row],[ypn]]) -> 1 | F15: 10.21.51985A
A16: 71986562 | B16: =TRIM(Table4[[#This Row],[ypn]]) -> 71986562 | C16: =Table4[[#This Row],[ypn]]=Table4[[#This Row],[trim]] -> FALSE | D16: =Table4[[#This Row],[ypn]]*1 -> 71986562 | E16: =TYPE(Table4[[#This Row],[ypn]]) -> 1 | F16: 10.21.77353A | G16: c
A17: 71987958 | B17: =TRIM(Table4[[#This Row],[ypn]]) -> 71987958 | C17: =Table4[[#This Row],[ypn]]=Table4[[#This Row],[trim]] -> FALSE | D17: =Table4[[#This Row],[ypn]]*1 -> 71987958 | E17: =TYPE(Table4[[#This Row],[ypn]]) -> 1 | F17: 10.21.90707
A18: 71988082 | B18: =TRIM(Table4[[#This Row],[ypn]]) -> 71988082 | C18: =Table4[[#This Row],[ypn]]=Table4[[#This Row],[trim]] -> FALSE | D18: =Table4[[#This Row],[ypn]]*1 -> 71988082 | E18: =TYPE(Table4[[#This Row],[ypn]]) -> 1 | F18: 10.21.73020B
A19: 71989162 | B19: =TRIM(Table4[[#This Row],[ypn]]) -> 71989162 | C19: =Table4[[#This Row],[ypn]]=Table4[[#This Row],[trim]] -> FALSE | D19: =Table4[[#This Row],[ypn]]*1 -> 71989162 | E19: =TYPE(Table4[[#This Row],[ypn]]) -> 1 | F19: 10.21.77353
A20: 72191763 | B20: =TRIM(Table4[[#This Row],[ypn]]) -> 72191763 | C20: =Table4[[#This Row],[ypn]]=Table4[[#This Row],[trim]] -> FALSE | D20: =Table4[[#This Row],[ypn]]*1 -> 72191763 | E20: =TYPE(Table4[[#This Row],[ypn]]) -> 1 | F20: 10.21.43782
A21: 72893837 | B21: =TRIM(Table4[[#This Row],[ypn]]) -> 72893837 | C21: =Table4[[#This Row],[ypn]]=Table4[[#This Row],[trim]] -> FALSE | D21: =Table4[[#This Row],[ypn]]*1 -> 72893837 | E21: =TYPE(Table4[[#This Row],[ypn]]) -> 1 | F21: 10.21.37987A
A22: 72895381 | B22: =TRIM(Table4[[#This Row],[ypn]]) -> 72895381 | C22: =Table4[[#This Row],[ypn]]=Table4[[#This Row],[trim]] -> FALSE | D22: =Table4[[#This Row],[ypn]]*1 -> 72895381 | E22: =TYPE(Table4[[#This Row],[ypn]]) -> 1 | F22: 10.21.77348A
A23: 72980475 | B23: =TRIM(Table4[[#This Row],[ypn]]) -> 72980475 | C23: =Table4[[#This Row],[ypn]]=Table4[[#This Row],[trim]] -> FALSE | D23: =Table4[[#This Row],[ypn]]*1 -> 72980475 | E23: =TYPE(Table4[[#This Row],[ypn]]) -> 1 | F23: 10.21.80721A
A24: 72988085 | B24: =TRIM(Table4[[#This Row],[ypn]]) -> 72988085 | C24: =Table4[[#This Row],[ypn]]=Table4[[#This Row],[trim]] -> FALSE | D24: =Table4[[#This Row],[ypn]]*1 -> 72988085 | E24: =TYPE(Table4[[#This Row],[ypn]]) -> 1 | F24: 10.21.73035A
A25: 7003293002 | B25: =TRIM(Table4[[#This Row],[ypn]]) -> 7003293002 | C25: =Table4[[#This Row],[ypn]]=Table4[[#This Row],[trim]] -> FALSE | D25: =Table4[[#This Row],[ypn]]*1 -> 7003293002 | E25: =TYPE(Table4[[#This Row],[ypn]]) -> 1 | F25: 10.21.77058A
A26: 7003803702 | B26: =TRIM(Table4[[#This Row],[ypn]]) -> 7003803702 | C26: =Table4[[#This Row],[ypn]]=Table4[[#This Row],[trim]] -> FALSE | D26: =Table4[[#This Row],[ypn]]*1 -> 7003803702 | E26: =TYPE(Table4[[#This Row],[ypn]]) -> 1
A27: 7009741502 | B27: =TRIM(Table4[[#This Row],[ypn]]) -> 7009741502 | C27: =Table4[[#This Row],[ypn]]=Table4[[#This Row],[trim]] -> FALSE | D27: =Table4[[#This Row],[ypn]]*1 -> 7009741502 | E27: =TYPE(Table4[[#This Row],[ypn]]) -> 1
A28: 7047135830 | B28: =TRIM(Table4[[#This Row],[ypn]]) -> 7047135830 | C28: =Table4[[#This Row],[ypn]]=Table4[[#This Row],[trim]] -> FALSE | D28: =Table4[[#This Row],[ypn]]*1 -> 7047135830 | E28: =TYPE(Table4[[#This Row],[ypn]]) -> 1
A29: 7047186030 | B29: =TRIM(Table4[[#This Row],[ypn]]) -> 7047186030 | C29: =Table4[[#This Row],[ypn]]=Table4[[#This Row],[trim]] -> FALSE | D29: =Table4[[#This Row],[ypn]]*1 -> 7047186030 | E29: =TYPE(Table4[[#This Row],[ypn]]) -> 1 | F29: 10.21.69492 | G29: erozina TR
A30: 7047273930 | B30: =TRIM(Table4[[#This Row],[ypn]]) -> 7047273930 | C30: =Table4[[#This Row],[ypn]]=Table4[[#This Row],[trim]] -> FALSE | D30: =Table4[[#This Row],[ypn]]*1 -> 7047273930 | E30: =TYPE(Table4[[#This Row],[ypn]]) -> 1
A31: 7047305630 | B31: =TRIM(Table4[[#This Row],[ypn]]) -> 7047305630 | C31: =Table4[[#This Row],[ypn]]=Table4[[#This Row],[trim]] -> FALSE | D31: =Table4[[#This Row],[ypn]]*1 -> 7047305630 | E31: =TYPE(Table4[[#This Row],[ypn]]) -> 1
A32: 7052753130 | B32: =TRIM(Table4[[#This Row],[ypn]]) -> 7052753130 | C32: =Table4[[#This Row],[ypn]]=Table4[[#This Row],[trim]] -> FALSE | D32: =Table4[[#This Row],[ypn]]*1 -> 7052753130 | E32: =TYPE(Table4[[#This Row],[ypn]]) -> 1
A33: 7075244730 | B33: =TRIM(Table4[[#This Row],[ypn]]) -> 7075244730 | C33: =Table4[[#This Row],[ypn]]=Table4[[#This Row],[trim]] -> FALSE | D33: =Table4[[#This Row],[ypn]]*1 -> 7075244730 | E33: =TYPE(Table4[[#This Row],[ypn]]) -> 1 | F33: 10.21.83796A
A34: 7118605030 | B34: =TRIM(Table4[[#This Row],[ypn]]) -> 7118605030 | C34: =Table4[[#This Row],[ypn]]=Table4[[#This Row],[trim]] -> FALSE | D34: =Table4[[#This Row],[ypn]]*1 -> 7118605030 | E34: =TYPE(Table4[[#This Row],[ypn]]) -> 1 | F34: 10.21.43814A
A35: 7119131260 | B35: =TRIM(Table4[[#This Row],[ypn]]) -> 7119131260 | C35: =Table4[[#This Row],[ypn]]=Table4[[#This Row],[trim]] -> FALSE | D35: =Table4[[#This Row],[ypn]]*1 -> 7119131260 | E35: =TYPE(Table4[[#This Row],[ypn]]) -> 1 | F35: 10.21.71225A
A36: 7119131530 | B36: =TRIM(Table4[[#This Row],[ypn]]) -> 7119131530 | C36: =Table4[[#This Row],[ypn]]=Table4[[#This Row],[trim]] -> FALSE | D36: =Table4[[#This Row],[ypn]]*1 -> 7119131530 | E36: =TYPE(Table4[[#This Row],[ypn]]) -> 1 | F36: 10.21.38917A
A37: 7119141030 | B37: =TRIM(Table4[[#This Row],[ypn]]) -> 7119141030 | C37: =Table4[[#This Row],[ypn]]=Table4[[#This Row],[trim]] -> FALSE | D37: =Table4[[#This Row],[ypn]]*1 -> 7119141030 | E37: =TYPE(Table4[[#This Row],[ypn]]) -> 1 | F37: 10.21.43817B
